[2024-03-19T11:50:58.497+0200] {taskinstance.py:1979} INFO - Dependencies all met for dep_context=non-requeueable deps ti=<TaskInstance: dag_id_3.print_sql_output manual__2024-03-19T09:50:35.673628+00:00 [queued]>
[2024-03-19T11:50:58.506+0200] {taskinstance.py:1979} INFO - Dependencies all met for dep_context=requeueable deps ti=<TaskInstance: dag_id_3.print_sql_output manual__2024-03-19T09:50:35.673628+00:00 [queued]>
[2024-03-19T11:50:58.506+0200] {taskinstance.py:2193} INFO - Starting attempt 1 of 1
[2024-03-19T11:50:58.518+0200] {taskinstance.py:2214} INFO - Executing <Task(PythonOperator): print_sql_output> on 2024-03-19 09:50:35.673628+00:00
[2024-03-19T11:50:58.522+0200] {standard_task_runner.py:60} INFO - Started process 20545 to run task
[2024-03-19T11:50:58.529+0200] {standard_task_runner.py:87} INFO - Running: ['airflow', 'tasks', 'run', 'dag_id_3', 'print_sql_output', 'manual__2024-03-19T09:50:35.673628+00:00', '--job-id', '381', '--raw', '--subdir', 'DAGS_FOLDER/jobs_dag.py', '--cfg-path', '/var/folders/t6/vwjsg0jx26jcjdwn_gxhbjzc0000gp/T/tmpfz_c8w75']
[2024-03-19T11:50:58.532+0200] {standard_task_runner.py:88} INFO - Job 381: Subtask print_sql_output
[2024-03-19T11:50:58.619+0200] {task_command.py:423} INFO - Running <TaskInstance: dag_id_3.print_sql_output manual__2024-03-19T09:50:35.673628+00:00 [running]> on host C9843
[2024-03-19T11:50:58.768+0200] {taskinstance.py:2510} INFO - Exporting env vars: AIRFLOW_CTX_DAG_OWNER='airflow' AIRFLOW_CTX_DAG_ID='dag_id_3' AIRFLOW_CTX_TASK_ID='print_sql_output' AIRFLOW_CTX_EXECUTION_DATE='2024-03-19T09:50:35.673628+00:00' AIRFLOW_CTX_TRY_NUMBER='1' AIRFLOW_CTX_DAG_RUN_ID='manual__2024-03-19T09:50:35.673628+00:00'
[2024-03-19T11:50:58.801+0200] {logging_mixin.py:188} INFO - SQL Output:
[2024-03-19T11:50:58.802+0200] {taskinstance.py:2728} ERROR - Task failed with exception
Traceback (most recent call last):
  File "/usr/local/lib/python3.8/site-packages/airflow/models/taskinstance.py", line 444, in _execute_task
    result = _execute_callable(context=context, **execute_callable_kwargs)
  File "/usr/local/lib/python3.8/site-packages/airflow/models/taskinstance.py", line 414, in _execute_callable
    return execute_callable(context=context, **execute_callable_kwargs)
  File "/usr/local/lib/python3.8/site-packages/airflow/operators/python.py", line 200, in execute
    return_value = self.execute_callable()
  File "/usr/local/lib/python3.8/site-packages/airflow/operators/python.py", line 217, in execute_callable
    return self.python_callable(*self.op_args, **self.op_kwargs)
  File "/Users/abatcoveanu/airflow/dags/jobs_dag.py", line 193, in print_sql_output
    for row in sql_output:
TypeError: 'NoneType' object is not iterable
[2024-03-19T11:50:58.813+0200] {taskinstance.py:1149} INFO - Marking task as FAILED. dag_id=dag_id_3, task_id=print_sql_output, execution_date=20240319T095035, start_date=20240319T095058, end_date=20240319T095058
[2024-03-19T11:50:58.826+0200] {standard_task_runner.py:107} ERROR - Failed to execute job 381 for task print_sql_output ('NoneType' object is not iterable; 20545)
[2024-03-19T11:50:58.841+0200] {local_task_job_runner.py:234} INFO - Task exited with return code 1
[2024-03-19T11:50:58.861+0200] {taskinstance.py:3309} INFO - 0 downstream tasks scheduled from follow-on schedule check
