[2024-04-04T11:25:30.608+0300] {taskinstance.py:1979} INFO - Dependencies all met for dep_context=non-requeueable deps ti=<TaskInstance: trigger_dag.trigger_dag_task scheduled__2018-11-25T00:00:00+00:00 [queued]>
[2024-04-04T11:25:30.635+0300] {taskinstance.py:1979} INFO - Dependencies all met for dep_context=requeueable deps ti=<TaskInstance: trigger_dag.trigger_dag_task scheduled__2018-11-25T00:00:00+00:00 [queued]>
[2024-04-04T11:25:30.635+0300] {taskinstance.py:2193} INFO - Starting attempt 1 of 1
[2024-04-04T11:25:30.647+0300] {taskinstance.py:2214} INFO - Executing <Task(TriggerDagRunOperator): trigger_dag_task> on 2018-11-25 00:00:00+00:00
[2024-04-04T11:25:30.651+0300] {standard_task_runner.py:60} INFO - Started process 32352 to run task
[2024-04-04T11:25:30.659+0300] {standard_task_runner.py:87} INFO - Running: ['airflow', 'tasks', 'run', 'trigger_dag', 'trigger_dag_task', 'scheduled__2018-11-25T00:00:00+00:00', '--job-id', '1670', '--raw', '--subdir', 'DAGS_FOLDER/trigger_dag.py', '--cfg-path', '/var/folders/t6/vwjsg0jx26jcjdwn_gxhbjzc0000gp/T/tmpqfji_zxq']
[2024-04-04T11:25:30.661+0300] {standard_task_runner.py:88} INFO - Job 1670: Subtask trigger_dag_task
[2024-04-04T11:25:30.759+0300] {task_command.py:423} INFO - Running <TaskInstance: trigger_dag.trigger_dag_task scheduled__2018-11-25T00:00:00+00:00 [running]> on host C9843
[2024-04-04T11:25:30.904+0300] {taskinstance.py:2510} INFO - Exporting env vars: AIRFLOW_CTX_DAG_OWNER='airflow' AIRFLOW_CTX_DAG_ID='trigger_dag' AIRFLOW_CTX_TASK_ID='trigger_dag_task' AIRFLOW_CTX_EXECUTION_DATE='2018-11-25T00:00:00+00:00' AIRFLOW_CTX_TRY_NUMBER='1' AIRFLOW_CTX_DAG_RUN_ID='scheduled__2018-11-25T00:00:00+00:00'
[2024-04-04T11:25:31.042+0300] {trigger_dagrun.py:210} INFO - Waiting for dag_id_3 on 2024-04-04 08:25:30.906327+00:00 to become allowed state ['success'] ...
[2024-04-04T11:26:06.108+0300] {local_task_job_runner.py:280} WARNING - Recorded pid 32624 does not match the current pid 32352
[2024-04-04T11:26:06.128+0300] {process_utils.py:131} INFO - Sending 15 to group 32352. PIDs of all processes in the group: [32352]
[2024-04-04T11:26:06.128+0300] {process_utils.py:86} INFO - Sending the signal 15 to group 32352
[2024-04-04T11:26:06.128+0300] {taskinstance.py:2480} ERROR - Received SIGTERM. Terminating subprocesses.
[2024-04-04T11:26:06.148+0300] {taskinstance.py:2728} ERROR - Task failed with exception
Traceback (most recent call last):
  File "/usr/local/lib/python3.8/site-packages/airflow/models/taskinstance.py", line 444, in _execute_task
    result = _execute_callable(context=context, **execute_callable_kwargs)
  File "/usr/local/lib/python3.8/site-packages/airflow/models/taskinstance.py", line 414, in _execute_callable
    return execute_callable(context=context, **execute_callable_kwargs)
  File "/usr/local/lib/python3.8/site-packages/airflow/operators/trigger_dagrun.py", line 216, in execute
    time.sleep(self.poke_interval)
  File "/usr/local/lib/python3.8/site-packages/airflow/models/taskinstance.py", line 2482, in signal_handler
    raise AirflowException("Task received SIGTERM signal")
airflow.exceptions.AirflowException: Task received SIGTERM signal
[2024-04-04T11:26:06.155+0300] {taskinstance.py:1149} INFO - Marking task as FAILED. dag_id=trigger_dag, task_id=trigger_dag_task, execution_date=20181125T000000, start_date=20240404T082605, end_date=20240404T082606
[2024-04-04T11:26:06.190+0300] {standard_task_runner.py:107} ERROR - Failed to execute job 1670 for task trigger_dag_task (Task received SIGTERM signal; 32352)
[2024-04-04T11:26:06.271+0300] {process_utils.py:79} INFO - Process psutil.Process(pid=32352, status='terminated', exitcode=1, started='11:25:30') (32352) terminated with exit code 1
