[2024-03-28T12:22:06.020+0200] {taskinstance.py:1979} INFO - Dependencies all met for dep_context=non-requeueable deps ti=<TaskInstance: trigger_dag.process_result.sensor_triggered_dag manual__2024-03-28T10:20:54.384518+00:00 [queued]>
[2024-03-28T12:22:06.029+0200] {taskinstance.py:1979} INFO - Dependencies all met for dep_context=requeueable deps ti=<TaskInstance: trigger_dag.process_result.sensor_triggered_dag manual__2024-03-28T10:20:54.384518+00:00 [queued]>
[2024-03-28T12:22:06.030+0200] {taskinstance.py:2193} INFO - Starting attempt 1 of 1
[2024-03-28T12:22:06.043+0200] {taskinstance.py:2214} INFO - Executing <Task(ExternalTaskSensor): process_result.sensor_triggered_dag> on 2024-03-28 10:20:54.384518+00:00
[2024-03-28T12:22:06.047+0200] {standard_task_runner.py:60} INFO - Started process 29374 to run task
[2024-03-28T12:22:06.054+0200] {standard_task_runner.py:87} INFO - Running: ['airflow', 'tasks', 'run', 'trigger_dag', 'process_result.sensor_triggered_dag', 'manual__2024-03-28T10:20:54.384518+00:00', '--job-id', '1115', '--raw', '--subdir', 'DAGS_FOLDER/trigger_dag.py', '--cfg-path', '/var/folders/t6/vwjsg0jx26jcjdwn_gxhbjzc0000gp/T/tmpz2z1hmav']
[2024-03-28T12:22:06.057+0200] {standard_task_runner.py:88} INFO - Job 1115: Subtask process_result.sensor_triggered_dag
[2024-03-28T12:22:06.174+0200] {task_command.py:423} INFO - Running <TaskInstance: trigger_dag.process_result.sensor_triggered_dag manual__2024-03-28T10:20:54.384518+00:00 [running]> on host C9843
[2024-03-28T12:22:06.351+0200] {taskinstance.py:2510} INFO - Exporting env vars: AIRFLOW_CTX_DAG_OWNER='airflow' AIRFLOW_CTX_DAG_ID='trigger_dag' AIRFLOW_CTX_TASK_ID='process_result.sensor_triggered_dag' AIRFLOW_CTX_EXECUTION_DATE='2024-03-28T10:20:54.384518+00:00' AIRFLOW_CTX_TRY_NUMBER='1' AIRFLOW_CTX_DAG_RUN_ID='manual__2024-03-28T10:20:54.384518+00:00'
[2024-03-28T12:22:06.354+0200] {external_task.py:260} INFO - Poking for DAG 'dag_id_3' on 2024-03-28T10:25:54.384518+00:00 ... 
[2024-03-28T12:23:06.380+0200] {external_task.py:260} INFO - Poking for DAG 'dag_id_3' on 2024-03-28T10:25:54.384518+00:00 ... 
[2024-03-28T12:24:06.394+0200] {external_task.py:260} INFO - Poking for DAG 'dag_id_3' on 2024-03-28T10:25:54.384518+00:00 ... 
[2024-03-28T12:25:06.405+0200] {external_task.py:260} INFO - Poking for DAG 'dag_id_3' on 2024-03-28T10:25:54.384518+00:00 ... 
[2024-03-28T12:26:06.437+0200] {external_task.py:260} INFO - Poking for DAG 'dag_id_3' on 2024-03-28T10:25:54.384518+00:00 ... 
[2024-03-28T12:27:06.452+0200] {external_task.py:260} INFO - Poking for DAG 'dag_id_3' on 2024-03-28T10:25:54.384518+00:00 ... 
[2024-03-28T12:27:34.450+0200] {local_task_job_runner.py:280} WARNING - Recorded pid 31583 does not match the current pid 29374
[2024-03-28T12:27:34.464+0200] {process_utils.py:131} INFO - Sending 15 to group 29374. PIDs of all processes in the group: [29374]
[2024-03-28T12:27:34.464+0200] {process_utils.py:86} INFO - Sending the signal 15 to group 29374
[2024-03-28T12:27:34.465+0200] {taskinstance.py:2480} ERROR - Received SIGTERM. Terminating subprocesses.
[2024-03-28T12:27:34.484+0200] {taskinstance.py:2728} ERROR - Task failed with exception
Traceback (most recent call last):
  File "/usr/local/lib/python3.8/site-packages/airflow/models/taskinstance.py", line 444, in _execute_task
    result = _execute_callable(context=context, **execute_callable_kwargs)
  File "/usr/local/lib/python3.8/site-packages/airflow/models/taskinstance.py", line 414, in _execute_callable
    return execute_callable(context=context, **execute_callable_kwargs)
  File "/usr/local/lib/python3.8/site-packages/airflow/sensors/external_task.py", line 334, in execute
    super().execute(context)
  File "/usr/local/lib/python3.8/site-packages/airflow/sensors/base.py", line 293, in execute
    time.sleep(self._get_next_poke_interval(started_at, run_duration, try_number))
  File "/usr/local/lib/python3.8/site-packages/airflow/models/taskinstance.py", line 2482, in signal_handler
    raise AirflowException("Task received SIGTERM signal")
airflow.exceptions.AirflowException: Task received SIGTERM signal
[2024-03-28T12:27:34.490+0200] {taskinstance.py:1149} INFO - Marking task as FAILED. dag_id=trigger_dag, task_id=process_result.sensor_triggered_dag, execution_date=20240328T102054, start_date=20240328T102729, end_date=20240328T102734
[2024-03-28T12:27:34.502+0200] {standard_task_runner.py:107} ERROR - Failed to execute job 1115 for task process_result.sensor_triggered_dag (Task received SIGTERM signal; 29374)
[2024-03-28T12:27:34.522+0200] {process_utils.py:79} INFO - Process psutil.Process(pid=29374, status='terminated', exitcode=1, started='12:22:06') (29374) terminated with exit code 1
