[2024-03-29T11:15:31.261+0200] {taskinstance.py:1979} INFO - Dependencies all met for dep_context=non-requeueable deps ti=<TaskInstance: trigger_dag.trigger_dag_task manual__2024-03-29T09:15:23.899630+00:00 [queued]>
[2024-03-29T11:15:31.288+0200] {taskinstance.py:1979} INFO - Dependencies all met for dep_context=requeueable deps ti=<TaskInstance: trigger_dag.trigger_dag_task manual__2024-03-29T09:15:23.899630+00:00 [queued]>
[2024-03-29T11:15:31.289+0200] {taskinstance.py:2193} INFO - Starting attempt 1 of 1
[2024-03-29T11:15:31.305+0200] {taskinstance.py:2214} INFO - Executing <Task(TriggerDagRunOperator): trigger_dag_task> on 2024-03-29 09:15:23.899630+00:00
[2024-03-29T11:15:31.311+0200] {standard_task_runner.py:60} INFO - Started process 27892 to run task
[2024-03-29T11:15:31.318+0200] {standard_task_runner.py:87} INFO - Running: ['airflow', 'tasks', 'run', 'trigger_dag', 'trigger_dag_task', 'manual__2024-03-29T09:15:23.899630+00:00', '--job-id', '1179', '--raw', '--subdir', 'DAGS_FOLDER/trigger_dag.py', '--cfg-path', '/var/folders/t6/vwjsg0jx26jcjdwn_gxhbjzc0000gp/T/tmplulp8h0w']
[2024-03-29T11:15:31.322+0200] {standard_task_runner.py:88} INFO - Job 1179: Subtask trigger_dag_task
[2024-03-29T11:15:31.444+0200] {task_command.py:423} INFO - Running <TaskInstance: trigger_dag.trigger_dag_task manual__2024-03-29T09:15:23.899630+00:00 [running]> on host C9843
[2024-03-29T11:15:31.685+0200] {taskinstance.py:2510} INFO - Exporting env vars: AIRFLOW_CTX_DAG_OWNER='airflow' AIRFLOW_CTX_DAG_ID='trigger_dag' AIRFLOW_CTX_TASK_ID='trigger_dag_task' AIRFLOW_CTX_EXECUTION_DATE='2024-03-29T09:15:23.899630+00:00' AIRFLOW_CTX_TRY_NUMBER='1' AIRFLOW_CTX_DAG_RUN_ID='manual__2024-03-29T09:15:23.899630+00:00'
[2024-03-29T11:15:31.913+0200] {trigger_dagrun.py:210} INFO - Waiting for dag_id_3 on 2024-03-29 09:15:31.688190+00:00 to become allowed state ['success'] ...
[2024-03-29T11:16:16.952+0200] {local_task_job_runner.py:280} WARNING - Recorded pid 28260 does not match the current pid 27892
[2024-03-29T11:16:16.975+0200] {process_utils.py:131} INFO - Sending 15 to group 27892. PIDs of all processes in the group: [27892]
[2024-03-29T11:16:16.976+0200] {process_utils.py:86} INFO - Sending the signal 15 to group 27892
[2024-03-29T11:16:16.977+0200] {taskinstance.py:2480} ERROR - Received SIGTERM. Terminating subprocesses.
[2024-03-29T11:16:16.997+0200] {taskinstance.py:2728} ERROR - Task failed with exception
Traceback (most recent call last):
  File "/usr/local/lib/python3.8/site-packages/airflow/models/taskinstance.py", line 444, in _execute_task
    result = _execute_callable(context=context, **execute_callable_kwargs)
  File "/usr/local/lib/python3.8/site-packages/airflow/models/taskinstance.py", line 414, in _execute_callable
    return execute_callable(context=context, **execute_callable_kwargs)
  File "/usr/local/lib/python3.8/site-packages/airflow/operators/trigger_dagrun.py", line 216, in execute
    time.sleep(self.poke_interval)
  File "/usr/local/lib/python3.8/site-packages/airflow/models/taskinstance.py", line 2482, in signal_handler
    raise AirflowException("Task received SIGTERM signal")
airflow.exceptions.AirflowException: Task received SIGTERM signal
[2024-03-29T11:16:17.011+0200] {taskinstance.py:1149} INFO - Marking task as FAILED. dag_id=trigger_dag, task_id=trigger_dag_task, execution_date=20240329T091523, start_date=20240329T091614, end_date=20240329T091617
[2024-03-29T11:16:17.048+0200] {standard_task_runner.py:107} ERROR - Failed to execute job 1179 for task trigger_dag_task (Task received SIGTERM signal; 27892)
[2024-03-29T11:16:17.070+0200] {process_utils.py:79} INFO - Process psutil.Process(pid=27892, status='terminated', exitcode=1, started='11:15:31') (27892) terminated with exit code 1
