[2024-03-26T14:46:18.549+0200] {taskinstance.py:1979} INFO - Dependencies all met for dep_context=non-requeueable deps ti=<TaskInstance: trigger_dag.trigger_dag_task manual__2024-03-26T12:46:06.794037+00:00 [queued]>
[2024-03-26T14:46:18.584+0200] {taskinstance.py:1979} INFO - Dependencies all met for dep_context=requeueable deps ti=<TaskInstance: trigger_dag.trigger_dag_task manual__2024-03-26T12:46:06.794037+00:00 [queued]>
[2024-03-26T14:46:18.585+0200] {taskinstance.py:2193} INFO - Starting attempt 1 of 1
[2024-03-26T14:46:18.601+0200] {taskinstance.py:2214} INFO - Executing <Task(TriggerDagRunOperator): trigger_dag_task> on 2024-03-26 12:46:06.794037+00:00
[2024-03-26T14:46:18.605+0200] {standard_task_runner.py:60} INFO - Started process 12868 to run task
[2024-03-26T14:46:18.613+0200] {standard_task_runner.py:87} INFO - Running: ['airflow', 'tasks', 'run', 'trigger_dag', 'trigger_dag_task', 'manual__2024-03-26T12:46:06.794037+00:00', '--job-id', '570', '--raw', '--subdir', 'DAGS_FOLDER/trigger_dag.py', '--cfg-path', '/var/folders/t6/vwjsg0jx26jcjdwn_gxhbjzc0000gp/T/tmpga3a4q11']
[2024-03-26T14:46:18.615+0200] {standard_task_runner.py:88} INFO - Job 570: Subtask trigger_dag_task
[2024-03-26T14:46:18.705+0200] {task_command.py:423} INFO - Running <TaskInstance: trigger_dag.trigger_dag_task manual__2024-03-26T12:46:06.794037+00:00 [running]> on host C9843
[2024-03-26T14:46:18.951+0200] {taskinstance.py:2510} INFO - Exporting env vars: AIRFLOW_CTX_DAG_OWNER='airflow' AIRFLOW_CTX_DAG_ID='trigger_dag' AIRFLOW_CTX_TASK_ID='trigger_dag_task' AIRFLOW_CTX_EXECUTION_DATE='2024-03-26T12:46:06.794037+00:00' AIRFLOW_CTX_TRY_NUMBER='1' AIRFLOW_CTX_DAG_RUN_ID='manual__2024-03-26T12:46:06.794037+00:00'
[2024-03-26T14:46:19.048+0200] {taskinstance.py:2728} ERROR - Task failed with exception
Traceback (most recent call last):
  File "/usr/local/lib/python3.8/site-packages/airflow/models/taskinstance.py", line 444, in _execute_task
    result = _execute_callable(context=context, **execute_callable_kwargs)
  File "/usr/local/lib/python3.8/site-packages/airflow/models/taskinstance.py", line 414, in _execute_callable
    return execute_callable(context=context, **execute_callable_kwargs)
  File "/usr/local/lib/python3.8/site-packages/airflow/operators/trigger_dagrun.py", line 165, in execute
    dag_run = trigger_dag(
  File "/usr/local/lib/python3.8/site-packages/airflow/api/common/trigger_dag.py", line 122, in trigger_dag
    raise DagNotFound(f"Dag id {dag_id} not found in DagModel")
airflow.exceptions.DagNotFound: Dag id dag not found in DagModel
[2024-03-26T14:46:19.054+0200] {taskinstance.py:1149} INFO - Marking task as FAILED. dag_id=trigger_dag, task_id=trigger_dag_task, execution_date=20240326T124606, start_date=20240326T124618, end_date=20240326T124619
[2024-03-26T14:46:19.084+0200] {standard_task_runner.py:107} ERROR - Failed to execute job 570 for task trigger_dag_task (Dag id dag not found in DagModel; 12868)
[2024-03-26T14:46:19.106+0200] {local_task_job_runner.py:234} INFO - Task exited with return code 1
[2024-03-26T14:46:19.185+0200] {taskinstance.py:3309} INFO - 0 downstream tasks scheduled from follow-on schedule check
