[2024-03-19T12:00:29.842+0200] {taskinstance.py:1979} INFO - Dependencies all met for dep_context=non-requeueable deps ti=<TaskInstance: dag_id_3.insert_new_row_test manual__2024-03-19T10:00:14.042296+00:00 [queued]>
[2024-03-19T12:00:29.849+0200] {taskinstance.py:1979} INFO - Dependencies all met for dep_context=requeueable deps ti=<TaskInstance: dag_id_3.insert_new_row_test manual__2024-03-19T10:00:14.042296+00:00 [queued]>
[2024-03-19T12:00:29.849+0200] {taskinstance.py:2193} INFO - Starting attempt 1 of 1
[2024-03-19T12:00:29.878+0200] {taskinstance.py:2214} INFO - Executing <Task(PostgresOperator): insert_new_row_test> on 2024-03-19 10:00:14.042296+00:00
[2024-03-19T12:00:29.882+0200] {standard_task_runner.py:60} INFO - Started process 22811 to run task
[2024-03-19T12:00:29.888+0200] {standard_task_runner.py:87} INFO - Running: ['airflow', 'tasks', 'run', 'dag_id_3', 'insert_new_row_test', 'manual__2024-03-19T10:00:14.042296+00:00', '--job-id', '389', '--raw', '--subdir', 'DAGS_FOLDER/jobs_dag.py', '--cfg-path', '/var/folders/t6/vwjsg0jx26jcjdwn_gxhbjzc0000gp/T/tmpr5layutt']
[2024-03-19T12:00:29.891+0200] {standard_task_runner.py:88} INFO - Job 389: Subtask insert_new_row_test
[2024-03-19T12:00:29.986+0200] {task_command.py:423} INFO - Running <TaskInstance: dag_id_3.insert_new_row_test manual__2024-03-19T10:00:14.042296+00:00 [running]> on host C9843
[2024-03-19T12:00:30.153+0200] {taskinstance.py:2510} INFO - Exporting env vars: AIRFLOW_CTX_DAG_OWNER='airflow' AIRFLOW_CTX_DAG_ID='dag_id_3' AIRFLOW_CTX_TASK_ID='insert_new_row_test' AIRFLOW_CTX_EXECUTION_DATE='2024-03-19T10:00:14.042296+00:00' AIRFLOW_CTX_TRY_NUMBER='1' AIRFLOW_CTX_DAG_RUN_ID='manual__2024-03-19T10:00:14.042296+00:00'
[2024-03-19T12:00:30.155+0200] {sql.py:276} INFO - Executing: SELECT * FROM ab_users
[2024-03-19T12:00:30.184+0200] {base.py:83} INFO - Using connection ID 'Postgres_db' for task execution.
[2024-03-19T12:00:30.233+0200] {base.py:83} INFO - Using connection ID 'Postgres_db' for task execution.
[2024-03-19T12:00:30.239+0200] {sql.py:457} INFO - Running statement: SELECT * FROM ab_users, parameters: [96957247, 'None', datetime.datetime(2024, 3, 19, 12, 0, 29, 193594)]
[2024-03-19T12:00:30.242+0200] {taskinstance.py:2728} ERROR - Task failed with exception
Traceback (most recent call last):
  File "/usr/local/lib/python3.8/site-packages/airflow/models/taskinstance.py", line 444, in _execute_task
    result = _execute_callable(context=context, **execute_callable_kwargs)
  File "/usr/local/lib/python3.8/site-packages/airflow/models/taskinstance.py", line 414, in _execute_callable
    return execute_callable(context=context, **execute_callable_kwargs)
  File "/usr/local/lib/python3.8/site-packages/airflow/providers/common/sql/operators/sql.py", line 282, in execute
    output = hook.run(
  File "/usr/local/lib/python3.8/site-packages/airflow/providers/common/sql/hooks/sql.py", line 404, in run
    self._run_command(cur, sql_statement, parameters)
  File "/usr/local/lib/python3.8/site-packages/airflow/providers/common/sql/hooks/sql.py", line 460, in _run_command
    cur.execute(sql_statement, parameters)
psycopg2.errors.UndefinedTable: relation "ab_users" does not exist
LINE 1: SELECT * FROM ab_users
                      ^

[2024-03-19T12:00:30.255+0200] {taskinstance.py:1149} INFO - Marking task as FAILED. dag_id=dag_id_3, task_id=insert_new_row_test, execution_date=20240319T100014, start_date=20240319T100029, end_date=20240319T100030
[2024-03-19T12:00:30.283+0200] {standard_task_runner.py:107} ERROR - Failed to execute job 389 for task insert_new_row_test (relation "ab_users" does not exist
LINE 1: SELECT * FROM ab_users
                      ^
; 22811)
[2024-03-19T12:00:30.320+0200] {local_task_job_runner.py:234} INFO - Task exited with return code 1
[2024-03-19T12:00:30.346+0200] {taskinstance.py:3309} INFO - 0 downstream tasks scheduled from follow-on schedule check
