[2024-03-15T13:36:47.573+0200] {taskinstance.py:1979} INFO - Dependencies all met for dep_context=non-requeueable deps ti=<TaskInstance: dag_id_3.insert_new_row manual__2024-03-15T11:36:37.780798+00:00 [queued]>
[2024-03-15T13:36:47.582+0200] {taskinstance.py:1979} INFO - Dependencies all met for dep_context=requeueable deps ti=<TaskInstance: dag_id_3.insert_new_row manual__2024-03-15T11:36:37.780798+00:00 [queued]>
[2024-03-15T13:36:47.582+0200] {taskinstance.py:2193} INFO - Starting attempt 1 of 1
[2024-03-15T13:36:47.609+0200] {taskinstance.py:2214} INFO - Executing <Task(PostgresOperator): insert_new_row> on 2024-03-15 11:36:37.780798+00:00
[2024-03-15T13:36:47.613+0200] {standard_task_runner.py:60} INFO - Started process 57281 to run task
[2024-03-15T13:36:47.619+0200] {standard_task_runner.py:87} INFO - Running: ['airflow', 'tasks', 'run', 'dag_id_3', 'insert_new_row', 'manual__2024-03-15T11:36:37.780798+00:00', '--job-id', '194', '--raw', '--subdir', 'DAGS_FOLDER/jobs_dag.py', '--cfg-path', '/var/folders/t6/vwjsg0jx26jcjdwn_gxhbjzc0000gp/T/tmpprenlsyu']
[2024-03-15T13:36:47.621+0200] {standard_task_runner.py:88} INFO - Job 194: Subtask insert_new_row
[2024-03-15T13:36:47.709+0200] {task_command.py:423} INFO - Running <TaskInstance: dag_id_3.insert_new_row manual__2024-03-15T11:36:37.780798+00:00 [running]> on host C9843
[2024-03-15T13:36:47.877+0200] {taskinstance.py:2510} INFO - Exporting env vars: AIRFLOW_CTX_DAG_OWNER='airflow' AIRFLOW_CTX_DAG_ID='dag_id_3' AIRFLOW_CTX_TASK_ID='insert_new_row' AIRFLOW_CTX_EXECUTION_DATE='2024-03-15T11:36:37.780798+00:00' AIRFLOW_CTX_TRY_NUMBER='1' AIRFLOW_CTX_DAG_RUN_ID='manual__2024-03-15T11:36:37.780798+00:00'
[2024-03-15T13:36:47.880+0200] {sql.py:276} INFO - Executing: INSERT INTO table_name_3 VALUES (%s, %s, %s)
[2024-03-15T13:36:47.925+0200] {taskinstance.py:2728} ERROR - Task failed with exception
Traceback (most recent call last):
  File "/usr/local/lib/python3.8/site-packages/airflow/models/taskinstance.py", line 444, in _execute_task
    result = _execute_callable(context=context, **execute_callable_kwargs)
  File "/usr/local/lib/python3.8/site-packages/airflow/models/taskinstance.py", line 414, in _execute_callable
    return execute_callable(context=context, **execute_callable_kwargs)
  File "/usr/local/lib/python3.8/site-packages/airflow/providers/common/sql/operators/sql.py", line 277, in execute
    hook = self.get_db_hook()
  File "/usr/local/lib/python3.8/site-packages/airflow/providers/common/sql/operators/sql.py", line 188, in get_db_hook
    return self._hook
  File "/usr/local/Cellar/python@3.8/3.8.18_2/Frameworks/Python.framework/Versions/3.8/lib/python3.8/functools.py", line 967, in __get__
    val = self.func(instance)
  File "/usr/local/lib/python3.8/site-packages/airflow/providers/common/sql/operators/sql.py", line 150, in _hook
    conn = BaseHook.get_connection(conn_id)
  File "/usr/local/lib/python3.8/site-packages/airflow/hooks/base.py", line 82, in get_connection
    conn = Connection.get_connection_from_secrets(conn_id)
  File "/usr/local/lib/python3.8/site-packages/airflow/models/connection.py", line 514, in get_connection_from_secrets
    raise AirflowNotFoundException(f"The conn_id `{conn_id}` isn't defined")
airflow.exceptions.AirflowNotFoundException: The conn_id `your_postgres_connection_id` isn't defined
[2024-03-15T13:36:47.934+0200] {taskinstance.py:1149} INFO - Marking task as FAILED. dag_id=dag_id_3, task_id=insert_new_row, execution_date=20240315T113637, start_date=20240315T113647, end_date=20240315T113647
[2024-03-15T13:36:47.965+0200] {standard_task_runner.py:107} ERROR - Failed to execute job 194 for task insert_new_row (The conn_id `your_postgres_connection_id` isn't defined; 57281)
[2024-03-15T13:36:48.009+0200] {local_task_job_runner.py:234} INFO - Task exited with return code 1
[2024-03-15T13:36:48.030+0200] {taskinstance.py:3309} INFO - 0 downstream tasks scheduled from follow-on schedule check
