[2024-03-15T13:27:40.079+0200] {taskinstance.py:1979} INFO - Dependencies all met for dep_context=non-requeueable deps ti=<TaskInstance: dag_id_3.check_table_existence manual__2024-03-15T11:27:24.223978+00:00 [queued]>
[2024-03-15T13:27:40.089+0200] {taskinstance.py:1979} INFO - Dependencies all met for dep_context=requeueable deps ti=<TaskInstance: dag_id_3.check_table_existence manual__2024-03-15T11:27:24.223978+00:00 [queued]>
[2024-03-15T13:27:40.089+0200] {taskinstance.py:2193} INFO - Starting attempt 1 of 1
[2024-03-15T13:27:40.114+0200] {taskinstance.py:2214} INFO - Executing <Task(BranchPythonOperator): check_table_existence> on 2024-03-15 11:27:24.223978+00:00
[2024-03-15T13:27:40.118+0200] {standard_task_runner.py:60} INFO - Started process 54814 to run task
[2024-03-15T13:27:40.125+0200] {standard_task_runner.py:87} INFO - Running: ['airflow', 'tasks', 'run', 'dag_id_3', 'check_table_existence', 'manual__2024-03-15T11:27:24.223978+00:00', '--job-id', '171', '--raw', '--subdir', 'DAGS_FOLDER/jobs_dag.py', '--cfg-path', '/var/folders/t6/vwjsg0jx26jcjdwn_gxhbjzc0000gp/T/tmpctc9itcm']
[2024-03-15T13:27:40.127+0200] {standard_task_runner.py:88} INFO - Job 171: Subtask check_table_existence
[2024-03-15T13:27:40.219+0200] {task_command.py:423} INFO - Running <TaskInstance: dag_id_3.check_table_existence manual__2024-03-15T11:27:24.223978+00:00 [running]> on host C9843
[2024-03-15T13:27:40.373+0200] {taskinstance.py:2510} INFO - Exporting env vars: AIRFLOW_CTX_DAG_OWNER='airflow' AIRFLOW_CTX_DAG_ID='dag_id_3' AIRFLOW_CTX_TASK_ID='check_table_existence' AIRFLOW_CTX_EXECUTION_DATE='2024-03-15T11:27:24.223978+00:00' AIRFLOW_CTX_TRY_NUMBER='1' AIRFLOW_CTX_DAG_RUN_ID='manual__2024-03-15T11:27:24.223978+00:00'
[2024-03-15T13:27:40.376+0200] {taskinstance.py:2728} ERROR - Task failed with exception
Traceback (most recent call last):
  File "/usr/local/lib/python3.8/site-packages/airflow/models/taskinstance.py", line 444, in _execute_task
    result = _execute_callable(context=context, **execute_callable_kwargs)
  File "/usr/local/lib/python3.8/site-packages/airflow/models/taskinstance.py", line 414, in _execute_callable
    return execute_callable(context=context, **execute_callable_kwargs)
  File "/usr/local/lib/python3.8/site-packages/airflow/operators/python.py", line 234, in execute
    return self.do_branch(context, super().execute(context))
  File "/usr/local/lib/python3.8/site-packages/airflow/operators/python.py", line 200, in execute
    return_value = self.execute_callable()
  File "/usr/local/lib/python3.8/site-packages/airflow/operators/python.py", line 217, in execute_callable
    return self.python_callable(*self.op_args, **self.op_kwargs)
TypeError: check_table_existence() missing 1 required positional argument: 'sql_to_check_table_exist'
[2024-03-15T13:27:40.389+0200] {taskinstance.py:1149} INFO - Marking task as FAILED. dag_id=dag_id_3, task_id=check_table_existence, execution_date=20240315T112724, start_date=20240315T112740, end_date=20240315T112740
[2024-03-15T13:27:40.416+0200] {standard_task_runner.py:107} ERROR - Failed to execute job 171 for task check_table_existence (check_table_existence() missing 1 required positional argument: 'sql_to_check_table_exist'; 54814)
[2024-03-15T13:27:40.439+0200] {local_task_job_runner.py:234} INFO - Task exited with return code 1
[2024-03-15T13:27:40.474+0200] {logging_mixin.py:188} WARNING - /usr/local/lib/python3.8/site-packages/airflow/models/baseoperator.py:1201 AirflowProviderDeprecationWarning: Call to deprecated class PostgresOperator. (Please use `airflow.providers.common.sql.operators.sql.SQLExecuteQueryOperator`.Also, you can provide `hook_params={'schema': <database>}`.)
[2024-03-15T13:27:40.494+0200] {taskinstance.py:3309} INFO - 0 downstream tasks scheduled from follow-on schedule check
