[2024-03-28T10:08:57.219+0200] {taskinstance.py:1979} INFO - Dependencies all met for dep_context=non-requeueable deps ti=<TaskInstance: dagTaskGroup.subdag.sensor_triggered_dag manual__2024-03-20T09:51:00.188938+00:00 [queued]>
[2024-03-28T10:08:57.231+0200] {taskinstance.py:1979} INFO - Dependencies all met for dep_context=requeueable deps ti=<TaskInstance: dagTaskGroup.subdag.sensor_triggered_dag manual__2024-03-20T09:51:00.188938+00:00 [queued]>
[2024-03-28T10:08:57.232+0200] {taskinstance.py:2193} INFO - Starting attempt 1 of 1
[2024-03-28T10:08:57.269+0200] {taskinstance.py:2214} INFO - Executing <Task(ExternalTaskSensor): subdag.sensor_triggered_dag> on 2024-03-20 09:51:00.188938+00:00
[2024-03-28T10:08:57.273+0200] {standard_task_runner.py:60} INFO - Started process 4378 to run task
[2024-03-28T10:08:57.282+0200] {standard_task_runner.py:87} INFO - Running: ['airflow', 'tasks', 'run', 'dagTaskGroup', 'subdag.sensor_triggered_dag', 'manual__2024-03-20T09:51:00.188938+00:00', '--job-id', '899', '--raw', '--subdir', 'DAGS_FOLDER/subdag.py', '--cfg-path', '/var/folders/t6/vwjsg0jx26jcjdwn_gxhbjzc0000gp/T/tmpuuqpj0wr']
[2024-03-28T10:08:57.286+0200] {standard_task_runner.py:88} INFO - Job 899: Subtask subdag.sensor_triggered_dag
[2024-03-28T10:08:57.417+0200] {task_command.py:423} INFO - Running <TaskInstance: dagTaskGroup.subdag.sensor_triggered_dag manual__2024-03-20T09:51:00.188938+00:00 [running]> on host C9843
[2024-03-28T10:08:57.574+0200] {taskinstance.py:2510} INFO - Exporting env vars: AIRFLOW_CTX_DAG_OWNER='airflow' AIRFLOW_CTX_DAG_ID='dagTaskGroup' AIRFLOW_CTX_TASK_ID='subdag.sensor_triggered_dag' AIRFLOW_CTX_EXECUTION_DATE='2024-03-20T09:51:00.188938+00:00' AIRFLOW_CTX_TRY_NUMBER='1' AIRFLOW_CTX_DAG_RUN_ID='manual__2024-03-20T09:51:00.188938+00:00'
[2024-03-28T10:08:57.577+0200] {taskinstance.py:2728} ERROR - Task failed with exception
Traceback (most recent call last):
  File "/usr/local/lib/python3.8/site-packages/airflow/models/taskinstance.py", line 444, in _execute_task
    result = _execute_callable(context=context, **execute_callable_kwargs)
  File "/usr/local/lib/python3.8/site-packages/airflow/models/taskinstance.py", line 414, in _execute_callable
    return execute_callable(context=context, **execute_callable_kwargs)
  File "/usr/local/lib/python3.8/site-packages/airflow/sensors/external_task.py", line 334, in execute
    super().execute(context)
  File "/usr/local/lib/python3.8/site-packages/airflow/sensors/base.py", line 265, in execute
    raise e
  File "/usr/local/lib/python3.8/site-packages/airflow/sensors/base.py", line 247, in execute
    poke_return = self.poke(context)
  File "/usr/local/lib/python3.8/site-packages/airflow/utils/session.py", line 79, in wrapper
    return func(*args, session=session, **kwargs)
  File "/usr/local/lib/python3.8/site-packages/airflow/sensors/external_task.py", line 240, in poke
    dttm_filter = self._get_dttm_filter(context)
  File "/usr/local/lib/python3.8/site-packages/airflow/sensors/external_task.py", line 229, in _get_dttm_filter
    dttm = self._handle_execution_date_fn(context=context)
  File "/usr/local/lib/python3.8/site-packages/airflow/sensors/external_task.py", line 468, in _handle_execution_date_fn
    return kwargs_callable(logical_date, **kwargs)
  File "/usr/local/lib/python3.8/site-packages/airflow/utils/operator_helpers.py", line 211, in kwargs_func
    kwargs = determine_kwargs(func, args, kwargs)
  File "/usr/local/lib/python3.8/site-packages/airflow/utils/operator_helpers.py", line 197, in determine_kwargs
    return KeywordParameters.determine(func, args, kwargs).unpacking()
  File "/usr/local/lib/python3.8/site-packages/airflow/utils/operator_helpers.py", line 163, in determine
    raise ValueError(f"The key {name!r} in args is a part of kwargs and therefore reserved.")
ValueError: The key 'context' in args is a part of kwargs and therefore reserved.
[2024-03-28T10:08:57.609+0200] {taskinstance.py:1149} INFO - Marking task as FAILED. dag_id=dagTaskGroup, task_id=subdag.sensor_triggered_dag, execution_date=20240320T095100, start_date=20240328T080857, end_date=20240328T080857
[2024-03-28T10:08:57.627+0200] {standard_task_runner.py:107} ERROR - Failed to execute job 899 for task subdag.sensor_triggered_dag (The key 'context' in args is a part of kwargs and therefore reserved.; 4378)
[2024-03-28T10:08:57.639+0200] {local_task_job_runner.py:234} INFO - Task exited with return code 1
[2024-03-28T10:08:57.716+0200] {taskinstance.py:3309} INFO - 0 downstream tasks scheduled from follow-on schedule check
