[2024-04-04T11:31:26.659+0300] {taskinstance.py:1979} INFO - Dependencies all met for dep_context=non-requeueable deps ti=<TaskInstance: trigger_dag.process_result.sensor_triggered_dag manual__2024-04-04T08:29:22.873594+00:00 [queued]>
[2024-04-04T11:31:26.687+0300] {taskinstance.py:1979} INFO - Dependencies all met for dep_context=requeueable deps ti=<TaskInstance: trigger_dag.process_result.sensor_triggered_dag manual__2024-04-04T08:29:22.873594+00:00 [queued]>
[2024-04-04T11:31:26.688+0300] {taskinstance.py:2193} INFO - Starting attempt 1 of 1
[2024-04-04T11:31:26.707+0300] {taskinstance.py:2214} INFO - Executing <Task(ExternalTaskSensor): process_result.sensor_triggered_dag> on 2024-04-04 08:29:22.873594+00:00
[2024-04-04T11:31:26.714+0300] {standard_task_runner.py:60} INFO - Started process 34696 to run task
[2024-04-04T11:31:26.723+0300] {standard_task_runner.py:87} INFO - Running: ['airflow', 'tasks', 'run', 'trigger_dag', 'process_result.sensor_triggered_dag', 'manual__2024-04-04T08:29:22.873594+00:00', '--job-id', '1708', '--raw', '--subdir', 'DAGS_FOLDER/trigger_dag.py', '--cfg-path', '/var/folders/t6/vwjsg0jx26jcjdwn_gxhbjzc0000gp/T/tmpy5nfgpxy']
[2024-04-04T11:31:26.726+0300] {standard_task_runner.py:88} INFO - Job 1708: Subtask process_result.sensor_triggered_dag
[2024-04-04T11:31:26.864+0300] {task_command.py:423} INFO - Running <TaskInstance: trigger_dag.process_result.sensor_triggered_dag manual__2024-04-04T08:29:22.873594+00:00 [running]> on host C9843
[2024-04-04T11:31:27.058+0300] {taskinstance.py:2510} INFO - Exporting env vars: AIRFLOW_CTX_DAG_OWNER='airflow' AIRFLOW_CTX_DAG_ID='trigger_dag' AIRFLOW_CTX_TASK_ID='process_result.sensor_triggered_dag' AIRFLOW_CTX_EXECUTION_DATE='2024-04-04T08:29:22.873594+00:00' AIRFLOW_CTX_TRY_NUMBER='1' AIRFLOW_CTX_DAG_RUN_ID='manual__2024-04-04T08:29:22.873594+00:00'
[2024-04-04T11:31:27.106+0300] {logging_mixin.py:188} INFO - External DAG schedule interval: None
[2024-04-04T11:31:27.107+0300] {logging_mixin.py:188} INFO - Current DAG schedule interval: None
[2024-04-04T11:31:27.108+0300] {external_task.py:260} INFO - Poking for DAG 'dag_id_3' on 2024-04-04T08:29:22.873594+00:00 ... 
[2024-04-04T11:32:27.150+0300] {logging_mixin.py:188} INFO - External DAG schedule interval: None
[2024-04-04T11:32:27.151+0300] {logging_mixin.py:188} INFO - Current DAG schedule interval: None
[2024-04-04T11:32:27.152+0300] {external_task.py:260} INFO - Poking for DAG 'dag_id_3' on 2024-04-04T08:29:22.873594+00:00 ... 
[2024-04-04T11:33:27.191+0300] {logging_mixin.py:188} INFO - External DAG schedule interval: None
[2024-04-04T11:33:27.192+0300] {logging_mixin.py:188} INFO - Current DAG schedule interval: None
[2024-04-04T11:33:27.192+0300] {external_task.py:260} INFO - Poking for DAG 'dag_id_3' on 2024-04-04T08:29:22.873594+00:00 ... 
[2024-04-04T11:34:27.242+0300] {logging_mixin.py:188} INFO - External DAG schedule interval: None
[2024-04-04T11:34:27.243+0300] {logging_mixin.py:188} INFO - Current DAG schedule interval: None
[2024-04-04T11:34:27.244+0300] {external_task.py:260} INFO - Poking for DAG 'dag_id_3' on 2024-04-04T08:29:22.873594+00:00 ... 
[2024-04-04T11:35:14.456+0300] {local_task_job_runner.py:280} WARNING - Recorded pid 36316 does not match the current pid 34696
[2024-04-04T11:35:14.472+0300] {process_utils.py:131} INFO - Sending 15 to group 34696. PIDs of all processes in the group: [34696]
[2024-04-04T11:35:14.473+0300] {process_utils.py:86} INFO - Sending the signal 15 to group 34696
[2024-04-04T11:35:14.473+0300] {taskinstance.py:2480} ERROR - Received SIGTERM. Terminating subprocesses.
[2024-04-04T11:35:14.498+0300] {taskinstance.py:2728} ERROR - Task failed with exception
Traceback (most recent call last):
  File "/usr/local/lib/python3.8/site-packages/airflow/models/taskinstance.py", line 444, in _execute_task
    result = _execute_callable(context=context, **execute_callable_kwargs)
  File "/usr/local/lib/python3.8/site-packages/airflow/models/taskinstance.py", line 414, in _execute_callable
    return execute_callable(context=context, **execute_callable_kwargs)
  File "/usr/local/lib/python3.8/site-packages/airflow/sensors/external_task.py", line 334, in execute
    super().execute(context)
  File "/usr/local/lib/python3.8/site-packages/airflow/sensors/base.py", line 293, in execute
    time.sleep(self._get_next_poke_interval(started_at, run_duration, try_number))
  File "/usr/local/lib/python3.8/site-packages/airflow/models/taskinstance.py", line 2482, in signal_handler
    raise AirflowException("Task received SIGTERM signal")
airflow.exceptions.AirflowException: Task received SIGTERM signal
[2024-04-04T11:35:14.504+0300] {taskinstance.py:1149} INFO - Marking task as FAILED. dag_id=trigger_dag, task_id=process_result.sensor_triggered_dag, execution_date=20240404T082922, start_date=20240404T083511, end_date=20240404T083514
[2024-04-04T11:35:14.519+0300] {standard_task_runner.py:107} ERROR - Failed to execute job 1708 for task process_result.sensor_triggered_dag (Task received SIGTERM signal; 34696)
[2024-04-04T11:35:14.527+0300] {process_utils.py:79} INFO - Process psutil.Process(pid=34696, status='terminated', exitcode=1, started='11:31:26') (34696) terminated with exit code 1
